<?xml version="1.0" encoding="utf-8"?>
<!-- This URDF was automatically created by SolidWorks to URDF Exporter! Originally created by
Stephen Brawner (brawner@gmail.com) 
     Commit Version: 1.6.0-1-g15f4949  Build Version: 1.6.7594.29634
     For more information, please see http://wiki.ros.org/sw_urdf_exporter -->
<robot name="kuka_kr10_r1440" xmlns:xacro="http://wiki.ros.org/xacro">
  <link
    name="base_link">
    <inertial>
      <origin xyz="0 0 0" rpy="0 0 0" />
      <mass value="80.0" />
      <inertia ixx="1.6" ixy="0" ixz="0"
        iyy="1.6" iyz="0"
        izz="1.6" />
    </inertial>

    <visual>
      <origin
        xyz="0.92485 -1.6825 0"
        rpy="0 0 0" />
      <geometry>
        <mesh
          filename="package://my_robot_description/meshes/base_link.STL" />
      </geometry>
      <material
        name="">
        <color
          rgba="0.792156862745098 0.819607843137255 0.933333333333333 1" />
      </material>
    </visual>
    <collision>
      <origin
        xyz="0.92485 -1.6825 0"
        rpy="0 0 0" />
      <geometry>
        <mesh
          filename="package://my_robot_description/meshes/base_link.STL" />
      </geometry>
    </collision>
  </link>
  <link
    name="main">
    <inertial>
      <origin xyz="0 0 0" rpy="0 0 0" />
      <mass value="20.0" />
      <inertia ixx="0.4" ixy="0" ixz="0"
        iyy="0.4" iyz="0"
        izz="0.4" />
    </inertial>

    <visual>
      <origin
        xyz="0 0 0"
        rpy="0 0 0" />
      <geometry>
        <mesh
          filename="package://my_robot_description/meshes/main.STL" />
      </geometry>
      <material
        name="">
        <color
          rgba="0.792156862745098 0.819607843137255 0.933333333333333 1" />
      </material>
    </visual>
    <collision>
      <origin
        xyz="0 0 0"
        rpy="0 0 0" />
      <geometry>
        <mesh
          filename="package://my_robot_description/meshes/main.STL" />
      </geometry>
    </collision>
  </link>
  <joint
    name="joint_1"
    type="revolute">
    <origin
      xyz="0 0 0.20895"
      rpy="0 0 0" />
    <parent
      link="base_link" />
    <child
      link="main" />
    <axis
      xyz="0 0 1" />
    <limit
      lower="-2.9671"
      upper="2.9671"
      effort="1000.0"
      velocity="3.8397" />
  </joint>
  <link
    name="shoulder">
    <inertial>
      <origin xyz="0 0 0" rpy="0 0 0" />
      <mass value="18.0" />
      <inertia ixx="0.36" ixy="0" ixz="0"
        iyy="0.36" iyz="0"
        izz="0.36" />
    </inertial>

    <visual>
      <origin
        xyz="0 0 0"
        rpy="0 0 0" />
      <geometry>
        <mesh
          filename="package://my_robot_description/meshes/shoulder.STL" />
      </geometry>
      <material
        name="">
        <color
          rgba="0.792156862745098 0.819607843137255 0.933333333333333 1" />
      </material>
    </visual>
    <collision>
      <origin
        xyz="0 0 0"
        rpy="0 0 0" />
      <geometry>
        <mesh
          filename="package://my_robot_description/meshes/shoulder.STL" />
      </geometry>
    </collision>
  </link>
  <joint
    name="joint_2"
    type="revolute">
    <origin
      xyz="0.17 -0.0619 0.21305"
      rpy="0 0 0" />
    <parent
      link="main" />
    <child
      link="shoulder" />
    <axis
      xyz="0 1 0" />
    <limit
      lower="-3.2289"
      upper="1.1345"
      effort="1000.0"
      velocity="3.6652" />
  </joint>
  <link
    name="elbow">
    <inertial>
      <origin xyz="0 0 0" rpy="0 0 0" />
      <mass value="15.0" />
      <inertia ixx="0.30" ixy="0" ixz="0"
        iyy="0.30" iyz="0"
        izz="0.30" />
    </inertial>

    <visual>
      <origin
        xyz="0 0 0"
        rpy="0 0 0" />
      <geometry>
        <mesh
          filename="package://my_robot_description/meshes/elbow.STL" />
      </geometry>
      <material
        name="">
        <color
          rgba="0.792156862745098 0.819607843137255 0.933333333333333 1" />
      </material>
    </visual>
    <collision>
      <origin
        xyz="0 0 0"
        rpy="0 0 0" />
      <geometry>
        <mesh
          filename="package://my_robot_description/meshes/elbow.STL" />
      </geometry>
    </collision>
  </link>
  <joint
    name="joint_3"
    type="revolute">
    <origin
      xyz="0 0 0.61"
      rpy="0 0 0" />
    <parent
      link="shoulder" />
    <child
      link="elbow" />
    <axis
      xyz="0 1 0" />
    <limit
      lower="-2.3911"
      upper="2.8449"
      effort="1000.0"
      velocity="4.7124" />
  </joint>
  <link
    name="forearm">
    <inertial>
      <origin xyz="0 0 0" rpy="0 0 0" />
      <mass value="9.0" />
      <inertia ixx="0.18" ixy="0" ixz="0"
        iyy="0.18" iyz="0"
        izz="0.18" />
    </inertial>

    <visual>
      <origin
        xyz="0 0 0"
        rpy="0 0 0" />
      <geometry>
        <mesh
          filename="package://my_robot_description/meshes/forearm.STL" />
      </geometry>
      <material
        name="">
        <color
          rgba="0.792156862745098 0.819607843137255 0.933333333333333 1" />
      </material>
    </visual>
    <collision>
      <origin
        xyz="0 0 0"
        rpy="0 0 0" />
      <geometry>
        <mesh
          filename="package://my_robot_description/meshes/forearm.STL" />
      </geometry>
    </collision>
  </link>
  <joint
    name="joint_4"
    type="revolute">
    <origin
      xyz="0.35 0.0619 0.02"
      rpy="0 0 0" />
    <parent
      link="elbow" />
    <child
      link="forearm" />
    <axis
      xyz="1 0 0" />
    <limit
      lower="-3.2289"
      upper="3.2289"
      effort="1000.0"
      velocity="6.6497" />
  </joint>
  <link
    name="end_effector">
    <inertial>
      <origin xyz="0 0 0" rpy="0 0 0" />
      <mass value="6.0" />
      <inertia ixx="0.12" ixy="0" ixz="0"
        iyy="0.12" iyz="0"
        izz="0.12" />
    </inertial>

    <visual>
      <origin
        xyz="0 0 0"
        rpy="0 0 0" />
      <geometry>
        <mesh
          filename="package://my_robot_description/meshes/end_effector.STL" />
      </geometry>
      <material
        name="">
        <color
          rgba="0.792156862745098 0.819607843137255 0.933333333333333 1" />
      </material>
    </visual>
    <collision>
      <origin
        xyz="0 0 0"
        rpy="0 0 0" />
      <geometry>
        <mesh
          filename="package://my_robot_description/meshes/end_effector.STL" />
      </geometry>
    </collision>
  </link>
  <joint
    name="joint_5"
    type="revolute">
    <origin
      xyz="0.31 0 0"
      rpy="0 0 0" />
    <parent
      link="forearm" />
    <child
      link="end_effector" />
    <axis
      xyz="0 1 0" />
    <limit
      lower="-2.0944"
      upper="2.0944"
      effort="1000.0"
      velocity="5.428" />
  </joint>
  <link
    name="tip">
    <inertial>
      <origin xyz="0 0 0" rpy="0 0 0" />
      <mass value="0.8" />
      <inertia ixx="0.016" ixy="0" ixz="0"
        iyy="0.016" iyz="0"
        izz="0.016" />
    </inertial>

    <visual>
      <origin
        xyz="0 0 0"
        rpy="0 0 0" />
      <geometry>
        <mesh
          filename="package://my_robot_description/meshes/tip.STL" />
      </geometry>
      <material
        name="">
        <color
          rgba="0.792156862745098 0.819607843137255 0.933333333333333 1" />
      </material>
    </visual>
    <collision>
      <origin
        xyz="0 0 0"
        rpy="0 0 0" />
      <geometry>
        <mesh
          filename="package://my_robot_description/meshes/tip.STL" />
      </geometry>
    </collision>
  </link>
  <joint
    name="joint_6"
    type="revolute">
    <origin
      xyz="0.082 0.0005 0"
      rpy="2.7324 0 0" />
    <parent
      link="end_effector" />
    <child
      link="tip" />
    <axis
      xyz="1 0 0" />
    <limit
      lower="-6.1087"
      upper="6.1087"
      effort="1000.0"
      velocity="8.238" />
  </joint>

  <link name="tool_link" />

  <joint name="hand_tool_joint" type="fixed">
    <parent link="tip" />
    <child link="tool_link" />
    <origin xyz="0.03 0 0" rpy="0 0 0" />
  </joint>
</robot>