<?xml version="1.0" encoding="UTF-8"?>
<robot name="drill_bit_module">

  <link name="cylinder_link">
    <visual>
      <geometry>
        <cylinder radius="0.4" length="0.2"/>
      </geometry>
      <origin xyz="0 0 0.1" rpy="0 0 0"/>
    </visual>
    <collision>
      <geometry>
        <cylinder radius="0.4" length="0.2"/>
      </geometry>
      <origin xyz="0 0 0.1" rpy="0 0 0"/>
    </collision>
  </link>

  <link name="drill_bit">
    <visual>
      <origin xyz="0 0 0" rpy="0 0 0"/> 
      <geometry>
        <mesh filename="package://kuka_trials/meshes/Bit.dae" scale="2 2 2"/>
      </geometry>
        <material name="Red">
            <color rgba="1 0 0 1"/>  
        </material>    
    </visual>
    <collision>
      <origin xyz="0 0 0" rpy="0 0 0"/>
      <geometry>
        <mesh filename="package://kuka_trials/meshes/Bit.dae" scale="2 2 2"/>
      </geometry>    
    </collision>
    <inertial>
      <origin xyz="0 0 0" rpy="0 0 0"/>
      <mass value="0.1"/>
      <inertia ixx="0.001" ixy="0.0" ixz="0.0" iyy="0.001" iyz="0.0" izz="0.001"/>
    </inertial>
  </link>

  <joint name="cylinder_to_drill_bit" type="revolute">
    <parent link="cylinder_link"/>
    <child link="drill_bit"/>
    <origin xyz="0 0 0.5" rpy="0 0 0"/>
    <axis xyz="0 0 1"/>
    <limit effort="10.0" velocity="1.0" lower="0" upper="6.28"/>
  </joint>

  <joint name="robot_to_drill_bit" type="fixed">
    <parent link="base_link"/>    
    <child link="cylinder_link"/>  
    <origin xyz="2 0 0" rpy="0 0 0"/>
  </joint>
</robot>
